2023-02-12 16:09:19,737 INFO: Microblog startup [in /Users/niklas/Documents/microblog/app/__init__.py:75]
2023-02-12 16:11:11,066 INFO: Microblog startup [in /Users/niklas/Documents/microblog/app/__init__.py:75]
2023-02-12 16:17:52,733 INFO: Microblog startup [in /Users/niklas/Documents/microblog/app/__init__.py:77]
2023-02-12 16:18:04,255 INFO: Microblog startup [in /Users/niklas/Documents/microblog/app/__init__.py:77]
2023-02-12 16:19:42,180 INFO: Microblog startup [in /Users/niklas/Documents/microblog/app/__init__.py:77]
2023-02-12 16:21:54,524 INFO: Microblog startup [in /Users/niklas/Documents/microblog/app/__init__.py:77]
2023-02-12 16:22:45,954 INFO: Microblog startup [in /Users/niklas/Documents/microblog/app/__init__.py:77]
2023-02-12 16:34:44,051 INFO: Microblog startup [in /Users/niklas/Documents/microblog/app/__init__.py:77]
2023-02-12 16:34:58,981 INFO: Microblog startup [in /Users/niklas/Documents/microblog/app/__init__.py:77]
2023-02-12 16:51:12,734 INFO: Microblog startup [in /Users/niklas/Documents/microblog/app/__init__.py:77]
2023-02-12 16:51:47,706 INFO: Microblog startup [in /Users/niklas/Documents/microblog/app/__init__.py:77]
2023-02-12 16:51:54,453 ERROR: Exception on / [GET] [in /Users/niklas/Documents/microblog/venv/lib/python3.8/site-packages/flask/app.py:1741]
Traceback (most recent call last):
  File "/Users/niklas/Documents/microblog/venv/lib/python3.8/site-packages/flask/app.py", line 2525, in wsgi_app
    response = self.full_dispatch_request()
  File "/Users/niklas/Documents/microblog/venv/lib/python3.8/site-packages/flask/app.py", line 1822, in full_dispatch_request
    rv = self.handle_user_exception(e)
  File "/Users/niklas/Documents/microblog/venv/lib/python3.8/site-packages/flask/app.py", line 1818, in full_dispatch_request
    rv = self.preprocess_request()
  File "/Users/niklas/Documents/microblog/venv/lib/python3.8/site-packages/flask/app.py", line 2309, in preprocess_request
    rv = self.ensure_sync(before_func)()
  File "/Users/niklas/Documents/microblog/app/main/routes.py", line 20, in before_request
    g.locale = str(get_locale())
  File "/Users/niklas/Documents/microblog/venv/lib/python3.8/site-packages/flask_babel/__init__.py", line 222, in get_locale
    babel = current_app.extensions['babel']
KeyError: 'babel'
2023-02-12 16:53:16,210 INFO: Microblog startup [in /Users/niklas/Documents/microblog/app/__init__.py:77]
2023-02-12 16:53:24,348 ERROR: Exception on / [GET] [in /Users/niklas/Documents/microblog/venv/lib/python3.8/site-packages/flask/app.py:1741]
Traceback (most recent call last):
  File "/Users/niklas/Documents/microblog/venv/lib/python3.8/site-packages/flask/app.py", line 2525, in wsgi_app
    response = self.full_dispatch_request()
  File "/Users/niklas/Documents/microblog/venv/lib/python3.8/site-packages/flask/app.py", line 1822, in full_dispatch_request
    rv = self.handle_user_exception(e)
  File "/Users/niklas/Documents/microblog/venv/lib/python3.8/site-packages/flask/app.py", line 1818, in full_dispatch_request
    rv = self.preprocess_request()
  File "/Users/niklas/Documents/microblog/venv/lib/python3.8/site-packages/flask/app.py", line 2309, in preprocess_request
    rv = self.ensure_sync(before_func)()
  File "/Users/niklas/Documents/microblog/app/main/routes.py", line 20, in before_request
    g.locale = str(get_locale())
  File "/Users/niklas/Documents/microblog/venv/lib/python3.8/site-packages/flask_babel/__init__.py", line 222, in get_locale
    babel = current_app.extensions['babel']
KeyError: 'babel'
2023-02-12 16:54:21,973 INFO: Microblog startup [in /Users/niklas/Documents/microblog/app/__init__.py:77]
2023-02-12 16:54:30,009 ERROR: Exception on / [GET] [in /Users/niklas/Documents/microblog/venv/lib/python3.8/site-packages/flask/app.py:1741]
Traceback (most recent call last):
  File "/Users/niklas/Documents/microblog/venv/lib/python3.8/site-packages/flask/app.py", line 2525, in wsgi_app
    response = self.full_dispatch_request()
  File "/Users/niklas/Documents/microblog/venv/lib/python3.8/site-packages/flask/app.py", line 1822, in full_dispatch_request
    rv = self.handle_user_exception(e)
  File "/Users/niklas/Documents/microblog/venv/lib/python3.8/site-packages/flask/app.py", line 1818, in full_dispatch_request
    rv = self.preprocess_request()
  File "/Users/niklas/Documents/microblog/venv/lib/python3.8/site-packages/flask/app.py", line 2309, in preprocess_request
    rv = self.ensure_sync(before_func)()
  File "/Users/niklas/Documents/microblog/app/main/routes.py", line 20, in before_request
    g.locale = str(get_locale())
  File "/Users/niklas/Documents/microblog/venv/lib/python3.8/site-packages/flask_babel/__init__.py", line 222, in get_locale
    babel = current_app.extensions['babel']
KeyError: 'babel'
2023-02-12 16:55:12,450 INFO: Microblog startup [in /Users/niklas/Documents/microblog/app/__init__.py:77]
2023-02-12 16:55:18,495 ERROR: Exception on / [GET] [in /Users/niklas/Documents/microblog/venv/lib/python3.8/site-packages/flask/app.py:1741]
Traceback (most recent call last):
  File "/Users/niklas/Documents/microblog/venv/lib/python3.8/site-packages/flask/app.py", line 2525, in wsgi_app
    response = self.full_dispatch_request()
  File "/Users/niklas/Documents/microblog/venv/lib/python3.8/site-packages/flask/app.py", line 1822, in full_dispatch_request
    rv = self.handle_user_exception(e)
  File "/Users/niklas/Documents/microblog/venv/lib/python3.8/site-packages/flask/app.py", line 1818, in full_dispatch_request
    rv = self.preprocess_request()
  File "/Users/niklas/Documents/microblog/venv/lib/python3.8/site-packages/flask/app.py", line 2309, in preprocess_request
    rv = self.ensure_sync(before_func)()
  File "/Users/niklas/Documents/microblog/app/main/routes.py", line 20, in before_request
    g.locale = str(get_locale())
  File "/Users/niklas/Documents/microblog/venv/lib/python3.8/site-packages/flask_babel/__init__.py", line 222, in get_locale
    babel = current_app.extensions['babel']
KeyError: 'babel'
2023-02-12 17:01:05,324 INFO: Microblog startup [in /Users/niklas/Documents/microblog/app/__init__.py:77]
2023-02-12 17:01:13,926 ERROR: Exception on / [GET] [in /Users/niklas/Documents/microblog/venv/lib/python3.8/site-packages/flask/app.py:1741]
Traceback (most recent call last):
  File "/Users/niklas/Documents/microblog/venv/lib/python3.8/site-packages/flask/app.py", line 2525, in wsgi_app
    response = self.full_dispatch_request()
  File "/Users/niklas/Documents/microblog/venv/lib/python3.8/site-packages/flask/app.py", line 1822, in full_dispatch_request
    rv = self.handle_user_exception(e)
  File "/Users/niklas/Documents/microblog/venv/lib/python3.8/site-packages/flask/app.py", line 1818, in full_dispatch_request
    rv = self.preprocess_request()
  File "/Users/niklas/Documents/microblog/venv/lib/python3.8/site-packages/flask/app.py", line 2309, in preprocess_request
    rv = self.ensure_sync(before_func)()
  File "/Users/niklas/Documents/microblog/app/main/routes.py", line 20, in before_request
    g.locale = str(get_locale())
  File "/Users/niklas/Documents/microblog/venv/lib/python3.8/site-packages/flask_babel/__init__.py", line 222, in get_locale
    babel = current_app.extensions['babel']
KeyError: 'babel'
2023-02-12 17:03:36,259 INFO: Microblog startup [in /Users/niklas/Documents/microblog/app/__init__.py:77]
2023-02-12 17:03:39,939 ERROR: Exception on / [GET] [in /Users/niklas/Documents/microblog/venv/lib/python3.8/site-packages/flask/app.py:1741]
Traceback (most recent call last):
  File "/Users/niklas/Documents/microblog/venv/lib/python3.8/site-packages/flask/app.py", line 2525, in wsgi_app
    response = self.full_dispatch_request()
  File "/Users/niklas/Documents/microblog/venv/lib/python3.8/site-packages/flask/app.py", line 1822, in full_dispatch_request
    rv = self.handle_user_exception(e)
  File "/Users/niklas/Documents/microblog/venv/lib/python3.8/site-packages/flask/app.py", line 1818, in full_dispatch_request
    rv = self.preprocess_request()
  File "/Users/niklas/Documents/microblog/venv/lib/python3.8/site-packages/flask/app.py", line 2309, in preprocess_request
    rv = self.ensure_sync(before_func)()
  File "/Users/niklas/Documents/microblog/app/main/routes.py", line 20, in before_request
    g.locale = str(get_locale())
NameError: name 'get_locale' is not defined
2023-02-12 17:05:44,359 INFO: Microblog startup [in /Users/niklas/Documents/microblog/app/__init__.py:77]
2023-02-12 17:05:47,335 ERROR: Exception on / [GET] [in /Users/niklas/Documents/microblog/venv/lib/python3.8/site-packages/flask/app.py:1741]
Traceback (most recent call last):
  File "/Users/niklas/Documents/microblog/venv/lib/python3.8/site-packages/flask/app.py", line 2525, in wsgi_app
    response = self.full_dispatch_request()
  File "/Users/niklas/Documents/microblog/venv/lib/python3.8/site-packages/flask/app.py", line 1822, in full_dispatch_request
    rv = self.handle_user_exception(e)
  File "/Users/niklas/Documents/microblog/venv/lib/python3.8/site-packages/flask/app.py", line 1820, in full_dispatch_request
    rv = self.dispatch_request()
  File "/Users/niklas/Documents/microblog/venv/lib/python3.8/site-packages/flask/app.py", line 1796, in dispatch_request
    return self.ensure_sync(self.view_functions[rule.endpoint])(**view_args)
  File "/Users/niklas/Documents/microblog/venv/lib/python3.8/site-packages/flask_login/utils.py", line 290, in decorated_view
    return current_app.ensure_sync(func)(*args, **kwargs)
  File "/Users/niklas/Documents/microblog/app/main/routes.py", line 47, in index
    return render_template('index.html', title=_('Home'), form=form,
NameError: name '_' is not defined
2023-02-12 17:06:35,460 INFO: Microblog startup [in /Users/niklas/Documents/microblog/app/__init__.py:77]
