2023-02-25 16:44:25,469 ERROR: Exception on /home [GET] [in /Library/Frameworks/Python.framework/Versions/3.11/lib/python3.11/site-packages/flask/app.py:1741]
Traceback (most recent call last):
  File "/Library/Frameworks/Python.framework/Versions/3.11/lib/python3.11/site-packages/sqlalchemy/engine/base.py", line 1964, in _exec_single_context
    self.dialect.do_execute(
  File "/Library/Frameworks/Python.framework/Versions/3.11/lib/python3.11/site-packages/sqlalchemy/engine/default.py", line 747, in do_execute
    cursor.execute(statement, parameters)
sqlite3.OperationalError: database is locked

The above exception was the direct cause of the following exception:

Traceback (most recent call last):
  File "/Library/Frameworks/Python.framework/Versions/3.11/lib/python3.11/site-packages/flask/app.py", line 2525, in wsgi_app
    response = self.full_dispatch_request()
               ^^^^^^^^^^^^^^^^^^^^^^^^^^^^
  File "/Library/Frameworks/Python.framework/Versions/3.11/lib/python3.11/site-packages/flask/app.py", line 1822, in full_dispatch_request
    rv = self.handle_user_exception(e)
         ^^^^^^^^^^^^^^^^^^^^^^^^^^^^^
  File "/Library/Frameworks/Python.framework/Versions/3.11/lib/python3.11/site-packages/flask/app.py", line 1818, in full_dispatch_request
    rv = self.preprocess_request()
         ^^^^^^^^^^^^^^^^^^^^^^^^^
  File "/Library/Frameworks/Python.framework/Versions/3.11/lib/python3.11/site-packages/flask/app.py", line 2309, in preprocess_request
    rv = self.ensure_sync(before_func)()
         ^^^^^^^^^^^^^^^^^^^^^^^^^^^^^^^
  File "/Users/niklas/Documents/n1kl3r_TB2_WiSe_2223/app/main/routes.py", line 22, in before_request
    db.session.commit()
  File "/Library/Frameworks/Python.framework/Versions/3.11/lib/python3.11/site-packages/sqlalchemy/orm/scoping.py", line 538, in commit
    return self._proxied.commit()
           ^^^^^^^^^^^^^^^^^^^^^^
  File "/Library/Frameworks/Python.framework/Versions/3.11/lib/python3.11/site-packages/sqlalchemy/orm/session.py", line 1903, in commit
    trans.commit(_to_root=True)
  File "<string>", line 2, in commit
  File "/Library/Frameworks/Python.framework/Versions/3.11/lib/python3.11/site-packages/sqlalchemy/orm/state_changes.py", line 137, in _go
    ret_value = fn(self, *arg, **kw)
                ^^^^^^^^^^^^^^^^^^^^
  File "/Library/Frameworks/Python.framework/Versions/3.11/lib/python3.11/site-packages/sqlalchemy/orm/session.py", line 1218, in commit
    self._prepare_impl()
  File "<string>", line 2, in _prepare_impl
  File "/Library/Frameworks/Python.framework/Versions/3.11/lib/python3.11/site-packages/sqlalchemy/orm/state_changes.py", line 137, in _go
    ret_value = fn(self, *arg, **kw)
                ^^^^^^^^^^^^^^^^^^^^
  File "/Library/Frameworks/Python.framework/Versions/3.11/lib/python3.11/site-packages/sqlalchemy/orm/session.py", line 1193, in _prepare_impl
    self.session.flush()
  File "/Library/Frameworks/Python.framework/Versions/3.11/lib/python3.11/site-packages/sqlalchemy/orm/session.py", line 4140, in flush
    self._flush(objects)
  File "/Library/Frameworks/Python.framework/Versions/3.11/lib/python3.11/site-packages/sqlalchemy/orm/session.py", line 4276, in _flush
    with util.safe_reraise():
  File "/Library/Frameworks/Python.framework/Versions/3.11/lib/python3.11/site-packages/sqlalchemy/util/langhelpers.py", line 147, in __exit__
    raise exc_value.with_traceback(exc_tb)
  File "/Library/Frameworks/Python.framework/Versions/3.11/lib/python3.11/site-packages/sqlalchemy/orm/session.py", line 4237, in _flush
    flush_context.execute()
  File "/Library/Frameworks/Python.framework/Versions/3.11/lib/python3.11/site-packages/sqlalchemy/orm/unitofwork.py", line 467, in execute
    rec.execute(self)
  File "/Library/Frameworks/Python.framework/Versions/3.11/lib/python3.11/site-packages/sqlalchemy/orm/unitofwork.py", line 644, in execute
    util.preloaded.orm_persistence.save_obj(
  File "/Library/Frameworks/Python.framework/Versions/3.11/lib/python3.11/site-packages/sqlalchemy/orm/persistence.py", line 85, in save_obj
    _emit_update_statements(
  File "/Library/Frameworks/Python.framework/Versions/3.11/lib/python3.11/site-packages/sqlalchemy/orm/persistence.py", line 894, in _emit_update_statements
    c = connection.execute(
        ^^^^^^^^^^^^^^^^^^^
  File "/Library/Frameworks/Python.framework/Versions/3.11/lib/python3.11/site-packages/sqlalchemy/engine/base.py", line 1414, in execute
    return meth(
           ^^^^^
  File "/Library/Frameworks/Python.framework/Versions/3.11/lib/python3.11/site-packages/sqlalchemy/sql/elements.py", line 489, in _execute_on_connection
    return connection._execute_clauseelement(
           ^^^^^^^^^^^^^^^^^^^^^^^^^^^^^^^^^^
  File "/Library/Frameworks/Python.framework/Versions/3.11/lib/python3.11/site-packages/sqlalchemy/engine/base.py", line 1638, in _execute_clauseelement
    ret = self._execute_context(
          ^^^^^^^^^^^^^^^^^^^^^^
  File "/Library/Frameworks/Python.framework/Versions/3.11/lib/python3.11/site-packages/sqlalchemy/engine/base.py", line 1842, in _execute_context
    return self._exec_single_context(
           ^^^^^^^^^^^^^^^^^^^^^^^^^^
  File "/Library/Frameworks/Python.framework/Versions/3.11/lib/python3.11/site-packages/sqlalchemy/engine/base.py", line 1983, in _exec_single_context
    self._handle_dbapi_exception(
  File "/Library/Frameworks/Python.framework/Versions/3.11/lib/python3.11/site-packages/sqlalchemy/engine/base.py", line 2325, in _handle_dbapi_exception
    raise sqlalchemy_exception.with_traceback(exc_info[2]) from e
  File "/Library/Frameworks/Python.framework/Versions/3.11/lib/python3.11/site-packages/sqlalchemy/engine/base.py", line 1964, in _exec_single_context
    self.dialect.do_execute(
  File "/Library/Frameworks/Python.framework/Versions/3.11/lib/python3.11/site-packages/sqlalchemy/engine/default.py", line 747, in do_execute
    cursor.execute(statement, parameters)
sqlalchemy.exc.OperationalError: (sqlite3.OperationalError) database is locked
[SQL: UPDATE user SET last_seen=? WHERE user.id = ?]
[parameters: ('2023-02-25 15:44:20.229606', 2)]
(Background on this error at: https://sqlalche.me/e/20/e3q8)
2023-02-25 16:46:37,193 INFO: Microblog startup [in /Users/niklas/Documents/n1kl3r_TB2_WiSe_2223/app/__init__.py:77]
2023-02-25 16:54:29,095 INFO: Microblog startup [in /Users/niklas/Documents/n1kl3r_TB2_WiSe_2223/app/__init__.py:77]
2023-02-26 20:52:25,879 INFO: Microblog startup [in /Users/niklas/Documents/n1kl3r_TB2_WiSe_2223/app/__init__.py:77]
2023-02-27 17:43:19,805 INFO: Microblog startup [in /Users/niklas/Documents/n1kl3r_TB2_WiSe_2223/app/__init__.py:77]
2023-02-27 18:09:54,889 INFO: Microblog startup [in /Users/niklas/Documents/n1kl3r_TB2_WiSe_2223/app/__init__.py:77]
2023-02-27 18:11:06,463 INFO: Netwarn startup [in /Users/niklas/Documents/n1kl3r_TB2_WiSe_2223/app/__init__.py:77]
2023-02-28 10:14:19,154 INFO: Netwarn startup [in /Users/niklas/Documents/n1kl3r_TB2_WiSe_2223/app/__init__.py:77]
2023-02-28 10:20:15,911 INFO: Netwarn startup [in /Users/niklas/Documents/n1kl3r_TB2_WiSe_2223/app/__init__.py:77]
2023-02-28 10:20:20,115 ERROR: Exception on /auth/login [GET] [in /Library/Frameworks/Python.framework/Versions/3.11/lib/python3.11/site-packages/flask/app.py:1741]
Traceback (most recent call last):
  File "/Library/Frameworks/Python.framework/Versions/3.11/lib/python3.11/site-packages/flask/app.py", line 2525, in wsgi_app
    response = self.full_dispatch_request()
               ^^^^^^^^^^^^^^^^^^^^^^^^^^^^
  File "/Library/Frameworks/Python.framework/Versions/3.11/lib/python3.11/site-packages/flask/app.py", line 1822, in full_dispatch_request
    rv = self.handle_user_exception(e)
         ^^^^^^^^^^^^^^^^^^^^^^^^^^^^^
  File "/Library/Frameworks/Python.framework/Versions/3.11/lib/python3.11/site-packages/flask/app.py", line 1820, in full_dispatch_request
    rv = self.dispatch_request()
         ^^^^^^^^^^^^^^^^^^^^^^^
  File "/Library/Frameworks/Python.framework/Versions/3.11/lib/python3.11/site-packages/flask/app.py", line 1796, in dispatch_request
    return self.ensure_sync(self.view_functions[rule.endpoint])(**view_args)
           ^^^^^^^^^^^^^^^^^^^^^^^^^^^^^^^^^^^^^^^^^^^^^^^^^^^^^^^^^^^^^^^^^
  File "/Users/niklas/Documents/n1kl3r_TB2_WiSe_2223/app/auth/routes.py", line 28, in login
    return render_template('auth/login.html', title=_('Sign In'), form=form)
           ^^^^^^^^^^^^^^^^^^^^^^^^^^^^^^^^^^^^^^^^^^^^^^^^^^^^^^^^^^^^^^^^^
  File "/Library/Frameworks/Python.framework/Versions/3.11/lib/python3.11/site-packages/flask/templating.py", line 147, in render_template
    return _render(app, template, context)
           ^^^^^^^^^^^^^^^^^^^^^^^^^^^^^^^
  File "/Library/Frameworks/Python.framework/Versions/3.11/lib/python3.11/site-packages/flask/templating.py", line 130, in _render
    rv = template.render(context)
         ^^^^^^^^^^^^^^^^^^^^^^^^
  File "/Library/Frameworks/Python.framework/Versions/3.11/lib/python3.11/site-packages/jinja2/environment.py", line 1301, in render
    self.environment.handle_exception()
  File "/Library/Frameworks/Python.framework/Versions/3.11/lib/python3.11/site-packages/jinja2/environment.py", line 936, in handle_exception
    raise rewrite_traceback_stack(source=source)
  File "/Users/niklas/Documents/n1kl3r_TB2_WiSe_2223/app/templates/auth/login.html", line 2, in top-level template code
    {% import 'bootstrap/wtf.html' as wtf %}
    ^^^^^^^^^^^^^^^^^^^^^^^^^
  File "/Users/niklas/Documents/n1kl3r_TB2_WiSe_2223/app/templates/base.html", line 1, in top-level template code
    {% extends 'bootstrap/base.html' %}
    ^^^^^^^^^^^^^^^^^^^^^^^^^
jinja2.exceptions.TemplateRuntimeError: extended multiple times
2023-02-28 10:21:25,514 INFO: Netwarn startup [in /Users/niklas/Documents/n1kl3r_TB2_WiSe_2223/app/__init__.py:77]
2023-02-28 10:22:50,138 INFO: Netwarn startup [in /Users/niklas/Documents/n1kl3r_TB2_WiSe_2223/app/__init__.py:77]
