2023-02-13 16:40:45,574 ERROR: Exception on /notifications [GET] [in /Users/niklas/Documents/microblog/venv/lib/python3.8/site-packages/flask/app.py:1741]
Traceback (most recent call last):
  File "/Users/niklas/Documents/microblog/venv/lib/python3.8/site-packages/flask/app.py", line 2525, in wsgi_app
    response = self.full_dispatch_request()
  File "/Users/niklas/Documents/microblog/venv/lib/python3.8/site-packages/flask/app.py", line 1822, in full_dispatch_request
    rv = self.handle_user_exception(e)
  File "/Users/niklas/Documents/microblog/venv/lib/python3.8/site-packages/flask/app.py", line 1820, in full_dispatch_request
    rv = self.dispatch_request()
  File "/Users/niklas/Documents/microblog/venv/lib/python3.8/site-packages/flask/app.py", line 1796, in dispatch_request
    return self.ensure_sync(self.view_functions[rule.endpoint])(**view_args)
  File "/Users/niklas/Documents/microblog/venv/lib/python3.8/site-packages/flask_login/utils.py", line 290, in decorated_view
    return current_app.ensure_sync(func)(*args, **kwargs)
  File "/Users/niklas/Documents/microblog/app/main/routes.py", line 131, in notifications
    Notification.timestamp > since).order_by(Notification.timestamp.asc())
NameError: name 'Notification' is not defined
2023-02-13 16:40:55,534 ERROR: Exception on /notifications [GET] [in /Users/niklas/Documents/microblog/venv/lib/python3.8/site-packages/flask/app.py:1741]
Traceback (most recent call last):
  File "/Users/niklas/Documents/microblog/venv/lib/python3.8/site-packages/flask/app.py", line 2525, in wsgi_app
    response = self.full_dispatch_request()
  File "/Users/niklas/Documents/microblog/venv/lib/python3.8/site-packages/flask/app.py", line 1822, in full_dispatch_request
    rv = self.handle_user_exception(e)
  File "/Users/niklas/Documents/microblog/venv/lib/python3.8/site-packages/flask/app.py", line 1820, in full_dispatch_request
    rv = self.dispatch_request()
  File "/Users/niklas/Documents/microblog/venv/lib/python3.8/site-packages/flask/app.py", line 1796, in dispatch_request
    return self.ensure_sync(self.view_functions[rule.endpoint])(**view_args)
  File "/Users/niklas/Documents/microblog/venv/lib/python3.8/site-packages/flask_login/utils.py", line 290, in decorated_view
    return current_app.ensure_sync(func)(*args, **kwargs)
  File "/Users/niklas/Documents/microblog/app/main/routes.py", line 131, in notifications
    Notification.timestamp > since).order_by(Notification.timestamp.asc())
NameError: name 'Notification' is not defined
2023-02-13 16:41:05,563 ERROR: Exception on /notifications [GET] [in /Users/niklas/Documents/microblog/venv/lib/python3.8/site-packages/flask/app.py:1741]
Traceback (most recent call last):
  File "/Users/niklas/Documents/microblog/venv/lib/python3.8/site-packages/flask/app.py", line 2525, in wsgi_app
    response = self.full_dispatch_request()
  File "/Users/niklas/Documents/microblog/venv/lib/python3.8/site-packages/flask/app.py", line 1822, in full_dispatch_request
    rv = self.handle_user_exception(e)
  File "/Users/niklas/Documents/microblog/venv/lib/python3.8/site-packages/flask/app.py", line 1820, in full_dispatch_request
    rv = self.dispatch_request()
  File "/Users/niklas/Documents/microblog/venv/lib/python3.8/site-packages/flask/app.py", line 1796, in dispatch_request
    return self.ensure_sync(self.view_functions[rule.endpoint])(**view_args)
  File "/Users/niklas/Documents/microblog/venv/lib/python3.8/site-packages/flask_login/utils.py", line 290, in decorated_view
    return current_app.ensure_sync(func)(*args, **kwargs)
  File "/Users/niklas/Documents/microblog/app/main/routes.py", line 131, in notifications
    Notification.timestamp > since).order_by(Notification.timestamp.asc())
NameError: name 'Notification' is not defined
2023-02-13 16:41:15,544 ERROR: Exception on /notifications [GET] [in /Users/niklas/Documents/microblog/venv/lib/python3.8/site-packages/flask/app.py:1741]
Traceback (most recent call last):
  File "/Users/niklas/Documents/microblog/venv/lib/python3.8/site-packages/flask/app.py", line 2525, in wsgi_app
    response = self.full_dispatch_request()
  File "/Users/niklas/Documents/microblog/venv/lib/python3.8/site-packages/flask/app.py", line 1822, in full_dispatch_request
    rv = self.handle_user_exception(e)
  File "/Users/niklas/Documents/microblog/venv/lib/python3.8/site-packages/flask/app.py", line 1820, in full_dispatch_request
    rv = self.dispatch_request()
  File "/Users/niklas/Documents/microblog/venv/lib/python3.8/site-packages/flask/app.py", line 1796, in dispatch_request
    return self.ensure_sync(self.view_functions[rule.endpoint])(**view_args)
  File "/Users/niklas/Documents/microblog/venv/lib/python3.8/site-packages/flask_login/utils.py", line 290, in decorated_view
    return current_app.ensure_sync(func)(*args, **kwargs)
  File "/Users/niklas/Documents/microblog/app/main/routes.py", line 131, in notifications
    Notification.timestamp > since).order_by(Notification.timestamp.asc())
NameError: name 'Notification' is not defined
2023-02-13 16:41:25,572 ERROR: Exception on /notifications [GET] [in /Users/niklas/Documents/microblog/venv/lib/python3.8/site-packages/flask/app.py:1741]
Traceback (most recent call last):
  File "/Users/niklas/Documents/microblog/venv/lib/python3.8/site-packages/flask/app.py", line 2525, in wsgi_app
    response = self.full_dispatch_request()
  File "/Users/niklas/Documents/microblog/venv/lib/python3.8/site-packages/flask/app.py", line 1822, in full_dispatch_request
    rv = self.handle_user_exception(e)
  File "/Users/niklas/Documents/microblog/venv/lib/python3.8/site-packages/flask/app.py", line 1820, in full_dispatch_request
    rv = self.dispatch_request()
  File "/Users/niklas/Documents/microblog/venv/lib/python3.8/site-packages/flask/app.py", line 1796, in dispatch_request
    return self.ensure_sync(self.view_functions[rule.endpoint])(**view_args)
  File "/Users/niklas/Documents/microblog/venv/lib/python3.8/site-packages/flask_login/utils.py", line 290, in decorated_view
    return current_app.ensure_sync(func)(*args, **kwargs)
  File "/Users/niklas/Documents/microblog/app/main/routes.py", line 131, in notifications
    Notification.timestamp > since).order_by(Notification.timestamp.asc())
NameError: name 'Notification' is not defined
2023-02-13 16:41:33,039 INFO: Microblog startup [in /Users/niklas/Documents/microblog/app/__init__.py:77]
2023-02-13 18:15:34,097 INFO: Microblog startup [in /Users/niklas/Documents/microblog/app/__init__.py:77]
2023-02-13 18:15:59,880 INFO: Microblog startup [in /Users/niklas/Documents/microblog/app/__init__.py:77]
2023-02-13 18:16:28,250 INFO: Microblog startup [in /Users/niklas/Documents/microblog/app/__init__.py:77]
2023-02-13 18:16:46,125 INFO: Microblog startup [in /Users/niklas/Documents/microblog/app/__init__.py:77]
2023-02-13 18:20:12,392 INFO: Microblog startup [in /Users/niklas/Documents/microblog/app/__init__.py:77]
2023-02-13 18:21:40,445 INFO: Microblog startup [in /Users/niklas/Documents/microblog/app/__init__.py:77]
2023-02-13 18:22:07,340 INFO: Microblog startup [in /Users/niklas/Documents/microblog/app/__init__.py:77]
2023-02-13 18:22:49,256 INFO: Microblog startup [in /Users/niklas/Documents/microblog/app/__init__.py:77]
2023-02-13 18:23:40,646 INFO: Microblog startup [in /Users/niklas/Documents/microblog/app/__init__.py:77]
2023-02-17 14:24:34,250 INFO: Microblog startup [in /Users/niklas/Documents/n1kl3r_TB2_WiSe_2223/app/__init__.py:77]
2023-02-17 14:25:08,304 INFO: Microblog startup [in /Users/niklas/Documents/n1kl3r_TB2_WiSe_2223/app/__init__.py:77]
2023-02-20 07:29:32,267 INFO: Microblog startup [in /Users/niklas/Documents/n1kl3r_TB2_WiSe_2223/app/__init__.py:77]
2023-02-20 07:38:48,846 INFO: Microblog startup [in /Users/niklas/Documents/n1kl3r_TB2_WiSe_2223/app/__init__.py:77]
2023-02-20 07:40:17,414 INFO: Microblog startup [in /Users/niklas/Documents/n1kl3r_TB2_WiSe_2223/app/__init__.py:77]
2023-02-20 07:40:25,549 ERROR: Exception on /map [GET] [in /Library/Frameworks/Python.framework/Versions/3.11/lib/python3.11/site-packages/flask/app.py:1741]
Traceback (most recent call last):
  File "/Library/Frameworks/Python.framework/Versions/3.11/lib/python3.11/site-packages/flask/app.py", line 2525, in wsgi_app
    response = self.full_dispatch_request()
               ^^^^^^^^^^^^^^^^^^^^^^^^^^^^
  File "/Library/Frameworks/Python.framework/Versions/3.11/lib/python3.11/site-packages/flask/app.py", line 1822, in full_dispatch_request
    rv = self.handle_user_exception(e)
         ^^^^^^^^^^^^^^^^^^^^^^^^^^^^^
  File "/Library/Frameworks/Python.framework/Versions/3.11/lib/python3.11/site-packages/flask/app.py", line 1820, in full_dispatch_request
    rv = self.dispatch_request()
         ^^^^^^^^^^^^^^^^^^^^^^^
  File "/Library/Frameworks/Python.framework/Versions/3.11/lib/python3.11/site-packages/flask/app.py", line 1796, in dispatch_request
    return self.ensure_sync(self.view_functions[rule.endpoint])(**view_args)
           ^^^^^^^^^^^^^^^^^^^^^^^^^^^^^^^^^^^^^^^^^^^^^^^^^^^^^^^^^^^^^^^^^
  File "/Users/niklas/Documents/n1kl3r_TB2_WiSe_2223/app/main/routes.py", line 232, in open_geo_app
    r = requests.get(url, verify= True)
        ^^^^^^^^
NameError: name 'requests' is not defined
2023-02-20 07:42:08,164 INFO: Microblog startup [in /Users/niklas/Documents/n1kl3r_TB2_WiSe_2223/app/__init__.py:77]
2023-02-20 07:42:42,953 INFO: Microblog startup [in /Users/niklas/Documents/n1kl3r_TB2_WiSe_2223/app/__init__.py:77]
