2023-02-12 17:18:34,818 ERROR: Exception on /explore [GET] [in /Users/niklas/Documents/microblog/venv/lib/python3.8/site-packages/flask/app.py:1741]
Traceback (most recent call last):
  File "/Users/niklas/Documents/microblog/venv/lib/python3.8/site-packages/flask/app.py", line 2525, in wsgi_app
    response = self.full_dispatch_request()
  File "/Users/niklas/Documents/microblog/venv/lib/python3.8/site-packages/flask/app.py", line 1822, in full_dispatch_request
    rv = self.handle_user_exception(e)
  File "/Users/niklas/Documents/microblog/venv/lib/python3.8/site-packages/flask/app.py", line 1820, in full_dispatch_request
    rv = self.dispatch_request()
  File "/Users/niklas/Documents/microblog/venv/lib/python3.8/site-packages/flask/app.py", line 1796, in dispatch_request
    return self.ensure_sync(self.view_functions[rule.endpoint])(**view_args)
  File "/Users/niklas/Documents/microblog/venv/lib/python3.8/site-packages/flask_login/utils.py", line 290, in decorated_view
    return current_app.ensure_sync(func)(*args, **kwargs)
  File "/Users/niklas/Documents/microblog/app/main/routes.py", line 63, in explore
    return render_template('index.html', title=_('Explore'),
NameError: name '_' is not defined
2023-02-12 17:18:35,848 ERROR: Exception on /user/NikLer [GET] [in /Users/niklas/Documents/microblog/venv/lib/python3.8/site-packages/flask/app.py:1741]
Traceback (most recent call last):
  File "/Users/niklas/Documents/microblog/venv/lib/python3.8/site-packages/flask/app.py", line 2525, in wsgi_app
    response = self.full_dispatch_request()
  File "/Users/niklas/Documents/microblog/venv/lib/python3.8/site-packages/flask/app.py", line 1822, in full_dispatch_request
    rv = self.handle_user_exception(e)
  File "/Users/niklas/Documents/microblog/venv/lib/python3.8/site-packages/flask/app.py", line 1820, in full_dispatch_request
    rv = self.dispatch_request()
  File "/Users/niklas/Documents/microblog/venv/lib/python3.8/site-packages/flask/app.py", line 1796, in dispatch_request
    return self.ensure_sync(self.view_functions[rule.endpoint])(**view_args)
  File "/Users/niklas/Documents/microblog/venv/lib/python3.8/site-packages/flask_login/utils.py", line 290, in decorated_view
    return current_app.ensure_sync(func)(*args, **kwargs)
  File "/Users/niklas/Documents/microblog/app/main/routes.py", line 81, in user
    return render_template('user.html', user=user, posts=posts.items,
  File "/Users/niklas/Documents/microblog/venv/lib/python3.8/site-packages/flask/templating.py", line 147, in render_template
    return _render(app, template, context)
  File "/Users/niklas/Documents/microblog/venv/lib/python3.8/site-packages/flask/templating.py", line 130, in _render
    rv = template.render(context)
  File "/Users/niklas/Documents/microblog/venv/lib/python3.8/site-packages/jinja2/environment.py", line 1301, in render
    self.environment.handle_exception()
  File "/Users/niklas/Documents/microblog/venv/lib/python3.8/site-packages/jinja2/environment.py", line 936, in handle_exception
    raise rewrite_traceback_stack(source=source)
  File "/Users/niklas/Documents/microblog/app/templates/user.html", line 1, in top-level template code
    {% extends "base.html" %}
  File "/Users/niklas/Documents/microblog/app/templates/base.html", line 1, in top-level template code
    {% extends 'bootstrap/base.html' %}
  File "/Users/niklas/Documents/microblog/venv/lib/python3.8/site-packages/flask_bootstrap/templates/bootstrap/base.html", line 1, in top-level template code
    {% block doc -%}
  File "/Users/niklas/Documents/microblog/venv/lib/python3.8/site-packages/flask_bootstrap/templates/bootstrap/base.html", line 4, in block 'doc'
    {%- block html %}
  File "/Users/niklas/Documents/microblog/venv/lib/python3.8/site-packages/flask_bootstrap/templates/bootstrap/base.html", line 20, in block 'html'
    {% block body -%}
  File "/Users/niklas/Documents/microblog/venv/lib/python3.8/site-packages/flask_bootstrap/templates/bootstrap/base.html", line 23, in block 'body'
    {% block content -%}
  File "/Users/niklas/Documents/microblog/app/templates/base.html", line 55, in block 'content'
    {% block app_content %}{% endblock %}
  File "/Users/niklas/Documents/microblog/app/templates/user.html", line 8, in block 'app_content'
    <h1>{{ _('User') }}: {{ user.username }}</h1>
  File "/Users/niklas/Documents/microblog/venv/lib/python3.8/site-packages/jinja2/utils.py", line 83, in from_obj
    if hasattr(obj, "jinja_pass_arg"):
jinja2.exceptions.UndefinedError: '_' is undefined
2023-02-12 17:18:36,499 ERROR: Exception on /auth/login [GET] [in /Users/niklas/Documents/microblog/venv/lib/python3.8/site-packages/flask/app.py:1741]
Traceback (most recent call last):
  File "/Users/niklas/Documents/microblog/venv/lib/python3.8/site-packages/flask/app.py", line 2525, in wsgi_app
    response = self.full_dispatch_request()
  File "/Users/niklas/Documents/microblog/venv/lib/python3.8/site-packages/flask/app.py", line 1822, in full_dispatch_request
    rv = self.handle_user_exception(e)
  File "/Users/niklas/Documents/microblog/venv/lib/python3.8/site-packages/flask/app.py", line 1820, in full_dispatch_request
    rv = self.dispatch_request()
  File "/Users/niklas/Documents/microblog/venv/lib/python3.8/site-packages/flask/app.py", line 1796, in dispatch_request
    return self.ensure_sync(self.view_functions[rule.endpoint])(**view_args)
  File "/Users/niklas/Documents/microblog/app/auth/routes.py", line 28, in login
    return render_template('auth/login.html', title=_('Sign In'), form=form)
  File "/Users/niklas/Documents/microblog/venv/lib/python3.8/site-packages/flask_babel/__init__.py", line 689, in gettext
    return get_domain().gettext(*args, **kwargs)
  File "/Users/niklas/Documents/microblog/venv/lib/python3.8/site-packages/flask_babel/__init__.py", line 682, in get_domain
    babel = current_app.extensions['babel']
KeyError: 'babel'
2023-02-12 17:18:39,977 ERROR: Exception on /auth/login [GET] [in /Users/niklas/Documents/microblog/venv/lib/python3.8/site-packages/flask/app.py:1741]
Traceback (most recent call last):
  File "/Users/niklas/Documents/microblog/venv/lib/python3.8/site-packages/flask/app.py", line 2525, in wsgi_app
    response = self.full_dispatch_request()
  File "/Users/niklas/Documents/microblog/venv/lib/python3.8/site-packages/flask/app.py", line 1822, in full_dispatch_request
    rv = self.handle_user_exception(e)
  File "/Users/niklas/Documents/microblog/venv/lib/python3.8/site-packages/flask/app.py", line 1820, in full_dispatch_request
    rv = self.dispatch_request()
  File "/Users/niklas/Documents/microblog/venv/lib/python3.8/site-packages/flask/app.py", line 1796, in dispatch_request
    return self.ensure_sync(self.view_functions[rule.endpoint])(**view_args)
  File "/Users/niklas/Documents/microblog/app/auth/routes.py", line 28, in login
    return render_template('auth/login.html', title=_('Sign In'), form=form)
  File "/Users/niklas/Documents/microblog/venv/lib/python3.8/site-packages/flask_babel/__init__.py", line 689, in gettext
    return get_domain().gettext(*args, **kwargs)
  File "/Users/niklas/Documents/microblog/venv/lib/python3.8/site-packages/flask_babel/__init__.py", line 682, in get_domain
    babel = current_app.extensions['babel']
KeyError: 'babel'
2023-02-12 17:19:51,729 INFO: Microblog startup [in /Users/niklas/Documents/microblog/app/__init__.py:77]
