2023-02-12 17:06:38,664 ERROR: Exception on / [GET] [in /Users/niklas/Documents/microblog/venv/lib/python3.8/site-packages/flask/app.py:1741]
Traceback (most recent call last):
  File "/Users/niklas/Documents/microblog/venv/lib/python3.8/site-packages/flask/app.py", line 2525, in wsgi_app
    response = self.full_dispatch_request()
  File "/Users/niklas/Documents/microblog/venv/lib/python3.8/site-packages/flask/app.py", line 1822, in full_dispatch_request
    rv = self.handle_user_exception(e)
  File "/Users/niklas/Documents/microblog/venv/lib/python3.8/site-packages/flask/app.py", line 1820, in full_dispatch_request
    rv = self.dispatch_request()
  File "/Users/niklas/Documents/microblog/venv/lib/python3.8/site-packages/flask/app.py", line 1796, in dispatch_request
    return self.ensure_sync(self.view_functions[rule.endpoint])(**view_args)
  File "/Users/niklas/Documents/microblog/venv/lib/python3.8/site-packages/flask_login/utils.py", line 290, in decorated_view
    return current_app.ensure_sync(func)(*args, **kwargs)
  File "/Users/niklas/Documents/microblog/app/main/routes.py", line 47, in index
    return render_template('index.html', title=_('Home'), form=form,
NameError: name '_' is not defined
2023-02-12 17:08:02,388 ERROR: Exception on / [GET] [in /Users/niklas/Documents/microblog/venv/lib/python3.8/site-packages/flask/app.py:1741]
Traceback (most recent call last):
  File "/Users/niklas/Documents/microblog/venv/lib/python3.8/site-packages/flask/app.py", line 2525, in wsgi_app
    response = self.full_dispatch_request()
  File "/Users/niklas/Documents/microblog/venv/lib/python3.8/site-packages/flask/app.py", line 1822, in full_dispatch_request
    rv = self.handle_user_exception(e)
  File "/Users/niklas/Documents/microblog/venv/lib/python3.8/site-packages/flask/app.py", line 1820, in full_dispatch_request
    rv = self.dispatch_request()
  File "/Users/niklas/Documents/microblog/venv/lib/python3.8/site-packages/flask/app.py", line 1796, in dispatch_request
    return self.ensure_sync(self.view_functions[rule.endpoint])(**view_args)
  File "/Users/niklas/Documents/microblog/venv/lib/python3.8/site-packages/flask_login/utils.py", line 290, in decorated_view
    return current_app.ensure_sync(func)(*args, **kwargs)
  File "/Users/niklas/Documents/microblog/app/main/routes.py", line 47, in index
    return render_template('index.html', title=_('Home'), form=form,
NameError: name '_' is not defined
2023-02-12 17:08:21,225 INFO: Microblog startup [in /Users/niklas/Documents/microblog/app/__init__.py:77]
2023-02-12 17:08:23,623 ERROR: Exception on / [GET] [in /Users/niklas/Documents/microblog/venv/lib/python3.8/site-packages/flask/app.py:1741]
Traceback (most recent call last):
  File "/Users/niklas/Documents/microblog/venv/lib/python3.8/site-packages/flask/app.py", line 2525, in wsgi_app
    response = self.full_dispatch_request()
  File "/Users/niklas/Documents/microblog/venv/lib/python3.8/site-packages/flask/app.py", line 1822, in full_dispatch_request
    rv = self.handle_user_exception(e)
  File "/Users/niklas/Documents/microblog/venv/lib/python3.8/site-packages/flask/app.py", line 1820, in full_dispatch_request
    rv = self.dispatch_request()
  File "/Users/niklas/Documents/microblog/venv/lib/python3.8/site-packages/flask/app.py", line 1796, in dispatch_request
    return self.ensure_sync(self.view_functions[rule.endpoint])(**view_args)
  File "/Users/niklas/Documents/microblog/venv/lib/python3.8/site-packages/flask_login/utils.py", line 290, in decorated_view
    return current_app.ensure_sync(func)(*args, **kwargs)
  File "/Users/niklas/Documents/microblog/app/main/routes.py", line 47, in index
    return render_template('index.html', title=_('Home'), form=form,
NameError: name '_' is not defined
2023-02-12 17:08:45,846 INFO: Microblog startup [in /Users/niklas/Documents/microblog/app/__init__.py:77]
2023-02-12 17:08:48,024 ERROR: Exception on / [GET] [in /Users/niklas/Documents/microblog/venv/lib/python3.8/site-packages/flask/app.py:1741]
Traceback (most recent call last):
  File "/Users/niklas/Documents/microblog/venv/lib/python3.8/site-packages/flask/app.py", line 2525, in wsgi_app
    response = self.full_dispatch_request()
  File "/Users/niklas/Documents/microblog/venv/lib/python3.8/site-packages/flask/app.py", line 1822, in full_dispatch_request
    rv = self.handle_user_exception(e)
  File "/Users/niklas/Documents/microblog/venv/lib/python3.8/site-packages/flask/app.py", line 1820, in full_dispatch_request
    rv = self.dispatch_request()
  File "/Users/niklas/Documents/microblog/venv/lib/python3.8/site-packages/flask/app.py", line 1796, in dispatch_request
    return self.ensure_sync(self.view_functions[rule.endpoint])(**view_args)
  File "/Users/niklas/Documents/microblog/venv/lib/python3.8/site-packages/flask_login/utils.py", line 290, in decorated_view
    return current_app.ensure_sync(func)(*args, **kwargs)
  File "/Users/niklas/Documents/microblog/app/main/routes.py", line 47, in index
    return render_template('index.html', title=_('Home'), form=form,
NameError: name '_' is not defined
2023-02-12 17:09:08,344 INFO: Microblog startup [in /Users/niklas/Documents/microblog/app/__init__.py:77]
2023-02-12 17:09:10,015 ERROR: Exception on / [GET] [in /Users/niklas/Documents/microblog/venv/lib/python3.8/site-packages/flask/app.py:1741]
Traceback (most recent call last):
  File "/Users/niklas/Documents/microblog/venv/lib/python3.8/site-packages/flask/app.py", line 2525, in wsgi_app
    response = self.full_dispatch_request()
  File "/Users/niklas/Documents/microblog/venv/lib/python3.8/site-packages/flask/app.py", line 1822, in full_dispatch_request
    rv = self.handle_user_exception(e)
  File "/Users/niklas/Documents/microblog/venv/lib/python3.8/site-packages/flask/app.py", line 1820, in full_dispatch_request
    rv = self.dispatch_request()
  File "/Users/niklas/Documents/microblog/venv/lib/python3.8/site-packages/flask/app.py", line 1796, in dispatch_request
    return self.ensure_sync(self.view_functions[rule.endpoint])(**view_args)
  File "/Users/niklas/Documents/microblog/venv/lib/python3.8/site-packages/flask_login/utils.py", line 290, in decorated_view
    return current_app.ensure_sync(func)(*args, **kwargs)
  File "/Users/niklas/Documents/microblog/app/main/routes.py", line 47, in index
    return render_template('index.html', title=_('Home'), form=form,
NameError: name '_' is not defined
2023-02-12 17:09:35,455 ERROR: Exception on / [GET] [in /Users/niklas/Documents/microblog/venv/lib/python3.8/site-packages/flask/app.py:1741]
Traceback (most recent call last):
  File "/Users/niklas/Documents/microblog/venv/lib/python3.8/site-packages/flask/app.py", line 2525, in wsgi_app
    response = self.full_dispatch_request()
  File "/Users/niklas/Documents/microblog/venv/lib/python3.8/site-packages/flask/app.py", line 1822, in full_dispatch_request
    rv = self.handle_user_exception(e)
  File "/Users/niklas/Documents/microblog/venv/lib/python3.8/site-packages/flask/app.py", line 1820, in full_dispatch_request
    rv = self.dispatch_request()
  File "/Users/niklas/Documents/microblog/venv/lib/python3.8/site-packages/flask/app.py", line 1796, in dispatch_request
    return self.ensure_sync(self.view_functions[rule.endpoint])(**view_args)
  File "/Users/niklas/Documents/microblog/venv/lib/python3.8/site-packages/flask_login/utils.py", line 290, in decorated_view
    return current_app.ensure_sync(func)(*args, **kwargs)
  File "/Users/niklas/Documents/microblog/app/main/routes.py", line 47, in index
    return render_template('index.html', title=('Home'), form=form,
NameError: name '_' is not defined
2023-02-12 17:09:42,797 INFO: Microblog startup [in /Users/niklas/Documents/microblog/app/__init__.py:77]
